<?xml version="1.0"?>
<robot name="cabinet">
  <link name ="rb0">
    <visual>
      <origin xyz='-0.314060 0.196507 0.054883' rpy='0.003277 -0.094095 -0.102833'/>
      <geometry>
        <mesh filename="meshes/cabinet.obj"  scale="1 1 1" />
      </geometry>
    </visual>

    <collision>
      <origin xyz='-0.314060 0.196507 0.054883' rpy='0.003277 -0.094095 -0.102833'/>
      <geometry>
        <mesh filename="meshes/cabinet.obj"  scale="1 1 1" />
      </geometry>
    </collision>


  </link>
  <joint name="j_0_1" type="prismatic">
    <parent link="rb0"/>
    <child link="rb1"/>
    <origin xyz="0.105792171617 -0.0736046820919 -0.426986027953" rpy="0 0 0 "/>
    <axis xyz="0.987920137453 -0.120690596023 0.0971986730736"/>
    <limit effort="30" velocity="1.0" lower="-3.1416" upper="3.1416"/>
  </joint>
  <joint name="j_0_fixed" type="fixed">
    <parent link="rb1"/>
    <child link="rb1_marker"/>
      <origin xyz="0.0 0.0 0.0" rpy="1.56055005754 0.0514254339295 2.96839888309"/>
    <limit effort="30" velocity="1.0" lower="-3.1416" upper="3.1416"/>
  </joint>
  <joint name="j_0_2" type="prismatic">
    <parent link="rb0"/>
    <child link="rb2"/>
    <origin xyz="0.11964604805 0.325155179319 -0.0341130064056" rpy="0 0 0 "/>
    <axis xyz="0.989369166984 -0.121103166429 0.0805150576107"/>
    <limit effort="30" velocity="1.0" lower="-3.1416" upper="3.1416"/>
  </joint>
  <joint name="j_1_fixed" type="fixed">
    <parent link="rb2"/>
    <child link="rb2_marker"/>
      <origin xyz="0.0 0.0 0.0" rpy="0.15127382539 -0.84908386829 -2.98318801372"/>
    <limit effort="30" velocity="1.0" lower="-3.1416" upper="3.1416"/>
  </joint>
  <link name ="rb1">
  </link>
  <link name ="rb1_marker">
    <visual>
      <origin xyz='0.213141 -0.130815 0.179854' rpy='1.570923 -0.074211 3.102909'/>
      <geometry>
        <mesh filename="meshes/cabinet_drawer_4th.obj"  scale="1 1 1" />
      </geometry>
    </visual>

     <collision>
      <origin xyz='0.213141 -0.130815 0.179854' rpy='1.570923 -0.074211 3.102909'/>
      <geometry>
        <mesh filename="meshes/cabinet_drawer_4th.obj"  scale="1 1 1" />
      </geometry>
    </collision>
    
  </link>
  <link name ="rb2">
  </link>
  <link name ="rb2_marker">
    <visual>
      <origin xyz='0.232805 0.032723 -0.259769' rpy='0.545144 -0.793681 2.536280'/>
      <geometry>
        <mesh filename="meshes/cabinet_drawer_top.obj"  scale="1 1 1" />
      </geometry>
    </visual>

    <collision>
      <origin xyz='0.232805 0.032723 -0.259769' rpy='0.545144 -0.793681 2.536280'/>
      <geometry>
        <mesh filename="meshes/cabinet_drawer_top.obj"  scale="1 1 1" />
      </geometry>
    </collision>

  </link>
</robot>
