<?xml version="1.0"?>
<robot name="laptop">
  <link name ="rb0">
    <visual>
      <origin xyz='0.058927 -0.090175 -0.151480' rpy='-0.726852 0.490066 1.157193'/>
      <geometry>
        <mesh filename="package://articulated_objects_db/data/objects/laptop/meshes/laptop_bottom.obj"  scale="1 1 1" />
      </geometry>
    </visual>
  </link>
  <joint name="j_0_1" type="revolute">
    <parent link="rb0"/>
    <child link="rb1"/>
    <origin xyz="0.180232991643 -0.000376197883956 -0.253333755529" rpy="0 0 0 "/>
    <axis xyz="-0.567047826018 0.228690873501 0.791300984068"/>
    <limit effort="30" velocity="1.0" lower="-3.1416" upper="3.1416"/>
  </joint>
  <joint name="j_0_fixed" type="fixed">
    <parent link="rb1"/>
    <child link="rb1_marker"/>
      <origin xyz="0.0263087083051 -0.133982253486 0.0573061278332" rpy="0.595515271901 -0.905902094014 2.78683164842"/>
    <limit effort="30" velocity="1.0" lower="-3.1416" upper="3.1416"/>
  </joint>
  <link name ="rb1">
  </link>
  <link name ="rb1_marker">
    <visual>
      <origin xyz='0.118160 -0.188569 -0.004876' rpy='0.135739 -1.170886 3.003704'/>
      <geometry>
        <mesh filename="package://articulated_objects_db/data/objects/laptop/meshes/laptop_top.obj"  scale="1 1 1" />
      </geometry>
    </visual>
  </link>
</robot>
