<?xml version="1.0"?>
<robot name="clamp">
  <link name ="rb0">
    <visual>
      <origin xyz='0.107480 0.474926 -0.063109' rpy='-0.307348 -0.069415 -0.293724'/>
      <geometry>
        <mesh filename="meshes/clamp_base.obj"  scale="1 1 1" />
      </geometry>
    </visual>

     <collision>
      <origin xyz='0.107480 0.474926 -0.063109' rpy='-0.307348 -0.069415 -0.293724'/>
      <geometry>
        <mesh filename="meshes/clamp_base.obj"  scale="1 1 1" />
      </geometry>
    </collision>

  </link>
  <joint name="j_0_1" type="prismatic">
    <parent link="rb0"/>
    <child link="rb1"/>
    <origin xyz="-0.0385699605233 0.347915904131 -0.00607227203669" rpy="0 0 0 "/>
    <axis xyz="-0.00391671127753 -0.999974753243 0.00592893321047"/>
    <limit effort="30" velocity="1.0" lower="-3.1416" upper="3.1416"/>
  </joint>
  <joint name="j_0_fixed" type="fixed">
    <parent link="rb1"/>
    <child link="rb1_marker"/>
      <origin xyz="0.0 0.0 0.0" rpy="-3.11678481357 0.00525497544478 0.93229115543"/>
    <limit effort="30" velocity="1.0" lower="-3.1416" upper="3.1416"/>
  </joint>
  <link name ="rb1">
  </link>
  <link name ="rb1_marker">
    <visual>
      <origin xyz='0.096234 0.023585 -0.000930' rpy='2.818620 0.181051 1.328693'/>
      <geometry>
        <mesh filename="meshes/clamp_handle.obj"  scale="1 1 1" />
      </geometry>
    </visual>

     <collision>
      <origin xyz='0.096234 0.023585 -0.000930' rpy='2.818620 0.181051 1.328693'/>
      <geometry>
        <mesh filename="meshes/clamp_handle.obj"  scale="1 1 1" />
      </geometry>
    </collision>

  </link>
</robot>
