<?xml version="1.0"?>
<robot name="ikeasmall">
  <link name ="rb0">
    <visual>
      <origin xyz='0.365970 0.123400 -0.462693' rpy='-0.000000 -0.061733 -0.091336'/>
      <geometry>
        <mesh filename="package://articulated_objects_db/data/objects/ikeasmall/meshes/ikeasmall_base.obj"  scale="1 1 1" />
      </geometry>
    </visual>
  </link>
  <joint name="j_0_2" type="prismatic">
    <parent link="rb0"/>
    <child link="rb2"/>
    <origin xyz="0.338679541953 -0.108210585648 -0.266701982116" rpy="0 0 0 "/>
    <axis xyz="0.995941653482 -0.0573652958422 0.0693501672145"/>
    <limit effort="30" velocity="1.0" lower="-3.1416" upper="3.1416"/>
  </joint>
  <joint name="j_0_fixed" type="fixed">
    <parent link="rb2"/>
    <child link="rb2_marker"/>
      <origin xyz="0.0 0.0 0.0" rpy="-1.55361807049 -0.0701876488589 -0.0102692740561"/>
    <limit effort="30" velocity="1.0" lower="-3.1416" upper="3.1416"/>
  </joint>
  <joint name="j_0_1" type="prismatic">
    <parent link="rb0"/>
    <child link="rb1"/>
    <origin xyz="0.39833866719 0.260149619428 -0.137811329749" rpy="0 0 0 "/>
    <axis xyz="0.995180385537 -0.064250767131 0.074079951168"/>
    <limit effort="30" velocity="1.0" lower="-3.1416" upper="3.1416"/>
  </joint>
  <joint name="j_1_fixed" type="fixed">
    <parent link="rb1"/>
    <child link="rb1_marker"/>
      <origin xyz="0.0 0.0 0.0" rpy="0.0759774693984 -0.817607501438 -2.8784033907"/>
    <limit effort="30" velocity="1.0" lower="-3.1416" upper="3.1416"/>
  </joint>
  <link name ="rb2">
  </link>
  <link name ="rb2_marker">
    <visual>
      <origin xyz='0.039773 0.041121 0.190295' rpy='1.571464 0.056354 0.000038'/>
      <geometry>
        <mesh filename="package://articulated_objects_db/data/objects/ikeasmall/meshes/ikeasmall_lower.obj"  scale="1 1 1" />
      </geometry>
    </visual>
  </link>
  <link name ="rb1">
  </link>
  <link name ="rb1_marker">
    <visual>
      <origin xyz='0.082051 0.159542 -0.055907' rpy='0.464755 -0.787265 2.561344'/>
      <geometry>
        <mesh filename="package://articulated_objects_db/data/objects/ikeasmall/meshes/ikeasmall_upper.obj"  scale="1 1 1" />
      </geometry>
    </visual>
  </link>
</robot>
