<?xml version="1.0"?>
<robot name="pliers">
  <link name ="rb0">
    <visual>
      <origin xyz='0.113459 0.022103 -0.004631' rpy='0.081767 0.166139 -1.655230'/>
      <geometry>
        <mesh filename="package://articulated_objects_db/data/objects/pliers/meshes/plier_right.obj"  scale="1 1 1" />
      </geometry>
    </visual>
  </link>
  <joint name="j_0_1" type="revolute">
    <parent link="rb0"/>
    <child link="rb1"/>
    <origin xyz="0.0176585590851 -0.0299033479141 -0.00889654501518" rpy="0 0 0 "/>
    <axis xyz="-0.0655486046566 -0.0794859462496 0.994678523331"/>
    <limit effort="30" velocity="1.0" lower="-3.1416" upper="3.1416"/>
  </joint>
  <joint name="j_0_fixed" type="fixed">
    <parent link="rb1"/>
    <child link="rb1_marker"/>
      <origin xyz="0.0750577405031 0.089193543935 0.0117309346362" rpy="-3.10683130842 -0.0526488123909 2.66201741394"/>
    <limit effort="30" velocity="1.0" lower="-3.1416" upper="3.1416"/>
  </joint>
  <link name ="rb1">
  </link>
  <link name ="rb1_marker">
    <visual>
      <origin xyz='-0.072164 -0.043532 -0.077714' rpy='-2.355783 -0.190300 -1.876381'/>
      <geometry>
        <mesh filename="package://articulated_objects_db/data/objects/pliers/meshes/plier_left.obj"  scale="1 1 1" />
      </geometry>
    </visual>
  </link>
</robot>
